Workbook

Sheet Modelo de dominio enriquecido
B2: Castaño Living
B3: Modelo de Dominio Enriquecido
B4: Tienda online de muebles de interior y exterior — documentación de dominio
B6: Contenido
B7: Listado Objetos de Dominio | C7: Los 12 objetos de dominio agrupados en 6 contextos delimitados
B8: Vendedor | C8: Objeto de dominio que representa la cuenta con la que un vendedor ingresa y gestiona pedidos dentro de Castaño Living.
B9: Administrador | C9: Objeto de dominio que representa la cuenta con la que un administrador gestiona bodega, envíos y el sistema en general.
B10: Producto | C10: Objeto de dominio que representa cada mueble de interior o exterior disponible para la venta en el catálogo.
B11: Almacén | C11: Objeto de dominio que representa el punto físico donde se exhiben los productos disponibles para la venta.
B12: Carrito | C12: Objeto de dominio que representa la selección temporal de productos que se arma antes de confirmar la compra.
B13: Pedido | C13: Objeto de dominio que representa una compra confirmada, desde su creación hasta la entrega.
B14: Pago | C14: Objeto de dominio que representa la transacción mediante la cual se cubre el valor de un pedido.
B15: Bodega | C15: Objeto de dominio que representa el control de existencias físicas de cada producto y su sincronización con la tienda.
B16: Envío | C16: Objeto de dominio que representa el proceso de transporte y entrega de un pedido confirmado al cliente.
B17: Cliente | C17: Objeto de dominio que representa a la persona para quien se realiza un pedido, identificada por su teléfono.
B18: DetallePedido | C18: Objeto de dominio de ruptura que representa cada línea de producto dentro de un pedido, con su cantidad y precio congelados.
B19: DetalleCarrito | C19: Objeto de dominio de ruptura que representa cada línea de producto dentro de un carrito, antes de confirmar la compra.
B22: Contextos delimitados
B23: Identidad y Acceso (Vendedor, Administrador) | C23: Gestiona quién opera Castaño Living: vendedores y administradores.
B24: Catálogo (Producto, Almacén) | C24: Gestiona los muebles que se ofrecen y los puntos donde se exhiben.
B25: Ventas (Carrito, DetalleCarrito, Pedido, DetallePedido, Cliente) | C25: Gestiona la selección de productos, su conversión en pedidos formales y a quién se le vende.
B26: Pagos (Pago) | C26: Gestiona el cobro de los pedidos.
B27: Inventario (Bodega) | C27: Gestiona las existencias físicas y su sincronización con la tienda.
B28: Logística (Envío) | C28: Gestiona el transporte y la entrega de los pedidos confirmados.

Sheet Listado Objetos de Dominio
A1: Nombre | B1: Descripcion | C1: TipoObjetoDominio | D1: Contexto
A2: Vendedor | B2: Objeto de dominio que representa la cuenta con la que un vendedor ingresa y gestiona pedidos dentro de Castaño Living. | C2: Propio | D2: Identidad y Acceso
A3: Administrador | B3: Objeto de dominio que representa la cuenta con la que un administrador gestiona bodega, envíos y el sistema en general. | C3: Propio | D3: Identidad y Acceso
A4: Producto | B4: Objeto de dominio que representa cada mueble de interior o exterior disponible para la venta en el catálogo. | C4: Propio | D4: Catálogo
A5: Almacén | B5: Objeto de dominio que representa el punto físico donde se exhiben los productos disponibles para la venta. | C5: Propio | D5: Catálogo
A6: Carrito | B6: Objeto de dominio que representa la selección temporal de productos que se arma antes de confirmar la compra. | C6: Propio | D6: Ventas
A7: Pedido | B7: Objeto de dominio que representa una compra confirmada, desde su creación hasta la entrega. | C7: Propio | D7: Ventas
A8: Pago | B8: Objeto de dominio que representa la transacción mediante la cual se cubre el valor de un pedido. | C8: Propio | D8: Pagos
A9: Bodega | B9: Objeto de dominio que representa el control de existencias físicas de cada producto y su sincronización con la tienda. | C9: Propio | D9: Inventario
A10: Envío | B10: Objeto de dominio que representa el proceso de transporte y entrega de un pedido confirmado al cliente. | C10: Propio | D10: Logística
A11: Cliente | B11: Objeto de dominio que representa a la persona para quien se realiza un pedido, identificada por su teléfono. | C11: Propio | D11: Ventas
A12: DetallePedido | B12: Objeto de dominio de ruptura que representa cada línea de producto dentro de un pedido, con su cantidad y precio congelados. | C12: Propio | D12: Ventas
A13: DetalleCarrito | B13: Objeto de dominio de ruptura que representa cada línea de producto dentro de un carrito, antes de confirmar la compra. | C13: Propio | D13: Ventas

Sheet Vendedor
A1: <-Volver al inicio
A2: Objeto de Dominio: | B2: ='Listado Objetos de Dominio'!$A$2 -> Vendedor
A3: Descripción: | B3: ='Listado Objetos de Dominio'!$B$2 -> Objeto de dominio que representa la cuenta con la que un vendedor ingresa y gestiona pedidos dentro de Castaño Living.
A4: Atributo | B4: Tipo de Dato | C4: Longitud mínima | D4: Longitud máxima | E4: Precisión | F4: Rango Inicial | G4: Rango Final | H4: Formato | I4: Valor por defecto | J4: Regla especial | K4: ¿Auto generado? | L4: ¿Calculado? | M4: ¿Obligatorio? | N4: ¿Sensible? | O4: ¿Identifica al registro? | P4: Descripción | Q4: =A20 -> Registrar vendedor | R4: =A21 -> Autenticar vendedor (Iniciar sesión) | S4: =A22 -> Actualizar datos de vendedor | T4: =A23 -> Desactivar cuenta
A5: IdVendedor | B5: Numérico Entero | C5: 1 | D5: 6 | E5: N/A | F5: 1 | G5: N/A | H5: Numérico | I5: N/A | J5: Único en todo el sistema; no se reutiliza si el vendedor se elimina | K5: Sí, por el propio sistema | L5: No | M5: Sí | N5: No | O5: Sí | P5: Identificador único de la cuenta de vendedor | Q5: Identifica la cuenta a registrar
A6: NombreUsuario | B6: Alfanumérico | C6: 4 | D6: 30 | E6: N/A | F6: N/A | G6: N/A | H6: Texto | I6: N/A | J6: Solo letras, números y guion bajo; no se permiten espacios | K6: No | L6: No | M6: Sí | N6: No | O6: Sí | P6: Nombre con el que el vendedor inicia sesión | Q6: Debe ser único al registrar | R6: Se digita para autenticar
A7: Contraseña | B7: Alfanumérico | C7: 8 | D7: 64 | E7: N/A | F7: N/A | G7: N/A | H7: Texto cifrado (hash) | I7: N/A | J7: Debe incluir mínimo una mayúscula, un número y un carácter especial | K7: No | L7: No | M7: Sí | N7: Sí | O7: No | P7: Clave de acceso almacenada como hash, nunca en texto plano | R7: Se valida contra el hash almacenado
A8: CorreoElectronico | B8: Alfanumérico | C8: 6 | D8: 100 | E8: N/A | F8: N/A | G8: N/A | H8: correo@dominio.com | I8: N/A | J8: Debe cumplir formato de correo válido y ser único | K8: No | L8: No | M8: Sí | N8: Sí | O8: No | P8: Medio de contacto y recuperación de cuenta
A9: Telefono | B9: Alfanumérico | C9: 7 | D9: 15 | E9: N/A | F9: N/A | G9: N/A | H9: Teléfono | I9: Sin registrar | J9: Debe ser un número de contacto válido | K9: No | L9: No | M9: No | N9: Sí | O9: No | P9: Número de contacto del vendedor | R9: Determina qué puede hacer tras iniciar sesión | S9: Solo un administrador puede reasignarlo
A10: FechaRegistro | B10: Fecha | C10: 10 | D10: 10 | E10: N/A | F10: N/A | G10: Fecha actual | H10: dd/mm/aaaa | I10: Fecha actual | J10: Debe ser igual o anterior a la fecha del sistema | K10: Sí | L10: Sí | M10: Sí | N10: No | O10: No | P10: Fecha en la que la cuenta fue creada
A11: Estado | B11: Enumeración | C11: 1 | D11: 1 | E11: N/A | F11: N/A | G11: N/A | H11: Texto | I11: Activo | J11: No puede tener más de un estado simultáneo | K11: No | L11: No | M11: Sí | N11: No | O11: No | P11: Indica si el vendedor puede iniciar sesión (Activo/Inactivo) | T11: Se cambia a Inactivo al desactivar la cuenta
A13: Combinaciones únicas
A14: Nombre combinación | B14: Descripción | C14: Atributos
A15: Cuenta única | B15: El NombreUsuario debe ser único en todo el sistema | C15: NombreUsuario
A16: Correo único | B16: El CorreoElectronico no puede repetirse entre vendedores | C16: CorreoElectronico
A18: Responsabilidad | C18: Descripción | G18: Entradas | J18: Salida | O18: Políticas (Reglas de Negocio) | Q18: Excepción
G19: Parámetro | H19: Tipo de dato | I19: Descripción | J19: Tipo de Dato | K19: Descripción | O19: Política | P19: Descripción | Q19: Detalle | R19: ¿Qué hago?
A20: Registrar vendedor | C20: Crea una nueva cuenta de vendedor validando que los datos sean únicos y válidos. | G20: NombreUsuario, Contraseña, CorreoElectronico, Telefono | H20: Alfanumérico, Alfanumérico, Alfanumérico, Alfanumérico | I20: Datos digitados en el formulario de registro | J20: Objeto Vendedor | K20: Cuenta creada con IdVendedor asignado y Estado=Activo | O20: Solo administrador | P20: Únicamente un Administrador puede registrar una nueva cuenta de Vendedor | Q20: El nombre de usuario o el correo ya está registrado | R20: Rechazar el registro y solicitar otro valor
A21: Autenticar vendedor (Iniciar sesión) | C21: Valida las credenciales ingresadas para habilitar el acceso del vendedor al sistema. | G21: NombreUsuario, Contraseña | H21: Alfanumérico, Alfanumérico | I21: Credenciales digitadas en el formulario de login | J21: Token de sesión | K21: Sesión activa asociada al IdVendedor | O21: Máximo de intentos | P21: Bloquear intentos adicionales tras 5 intentos fallidos en 10 minutos | Q21: Vendedor o contraseña incorrectos | R21: Mostrar un mensaje genérico de error sin revelar cuál dato falló
A22: Actualizar datos de vendedor | C22: Modifica el correo, teléfono o contraseña de una cuenta existente. | G22: IdVendedor, CampoAModificar, NuevoValor | H22: Numérico Entero, Texto, Texto | I22: Identificador de la cuenta y el dato a actualizar | J22: Objeto Vendedor | K22: Cuenta con los datos actualizados | O22: Validación de formato | P22: Los nuevos datos deben cumplir las mismas reglas del registro | Q22: El nuevo dato no cumple el formato | R22: Rechazar el cambio y mantener el dato anterior
A23: Desactivar cuenta | C23: Cambia el Estado del vendedor a Inactivo para impedir futuros inicios de sesión sin eliminar su historial. | G23: IdVendedor | H23: Numérico Entero | I23: Cuenta a desactivar | J23: Objeto Vendedor | K23: Cuenta con Estado=Inactivo | O23: Solo administrador | P23: Únicamente un administrador puede desactivar una cuenta de vendedor | Q23: El vendedor tiene pedidos en curso | R23: Reasignar los pedidos pendientes antes de desactivar

Sheet Administrador
A1: <-Volver al inicio
A2: Objeto de Dominio: | B2: ='Listado Objetos de Dominio'!$A$3 -> Administrador
A3: Descripción: | B3: ='Listado Objetos de Dominio'!$B$3 -> Objeto de dominio que representa la cuenta con la que un administrador gestiona bodega, envíos y el sistema en general.
A4: Atributo | B4: Tipo de Dato | C4: Longitud mínima | D4: Longitud máxima | E4: Precisión | F4: Rango Inicial | G4: Rango Final | H4: Formato | I4: Valor por defecto | J4: Regla especial | K4: ¿Auto generado? | L4: ¿Calculado? | M4: ¿Obligatorio? | N4: ¿Sensible? | O4: ¿Identifica al registro? | P4: Descripción | Q4: =A20 -> Registrar administrador | R4: =A21 -> Autenticar administrador (Iniciar sesión) | S4: =A22 -> Actualizar datos de administrador | T4: =A23 -> Desactivar cuenta
A5: IdAdministrador | B5: Numérico Entero | C5: 1 | D5: 6 | E5: N/A | F5: 1 | G5: N/A | H5: Numérico | I5: N/A | J5: Único en todo el sistema; no se reutiliza si el administrador se elimina | K5: Sí, por el propio sistema | L5: No | M5: Sí | N5: No | O5: Sí | P5: Identificador único de la cuenta de administrador | Q5: Identifica la cuenta a registrar
A6: NombreUsuario | B6: Alfanumérico | C6: 4 | D6: 30 | E6: N/A | F6: N/A | G6: N/A | H6: Texto | I6: N/A | J6: Solo letras, números y guion bajo; no se permiten espacios | K6: No | L6: No | M6: Sí | N6: No | O6: Sí | P6: Nombre con el que el administrador inicia sesión | Q6: Debe ser único al registrar | R6: Se digita para autenticar
A7: Contraseña | B7: Alfanumérico | C7: 8 | D7: 64 | E7: N/A | F7: N/A | G7: N/A | H7: Texto cifrado (hash) | I7: N/A | J7: Debe incluir mínimo una mayúscula, un número y un carácter especial | K7: No | L7: No | M7: Sí | N7: Sí | O7: No | P7: Clave de acceso almacenada como hash, nunca en texto plano | R7: Se valida contra el hash almacenado
A8: CorreoElectronico | B8: Alfanumérico | C8: 6 | D8: 100 | E8: N/A | F8: N/A | G8: N/A | H8: correo@dominio.com | I8: N/A | J8: Debe cumplir formato de correo válido y ser único | K8: No | L8: No | M8: Sí | N8: Sí | O8: No | P8: Medio de contacto y recuperación de cuenta
A9: Telefono | B9: Alfanumérico | C9: 7 | D9: 15 | E9: N/A | F9: N/A | G9: N/A | H9: Teléfono | I9: Sin registrar | J9: Debe ser un número de contacto válido | K9: No | L9: No | M9: No | N9: Sí | O9: No | P9: Número de contacto del administrador | R9: Determina qué puede hacer tras iniciar sesión | S9: Solo un administrador puede reasignarlo
A10: FechaRegistro | B10: Fecha | C10: 10 | D10: 10 | E10: N/A | F10: N/A | G10: Fecha actual | H10: dd/mm/aaaa | I10: Fecha actual | J10: Debe ser igual o anterior a la fecha del sistema | K10: Sí | L10: Sí | M10: Sí | N10: No | O10: No | P10: Fecha en la que la cuenta fue creada
A11: Estado | B11: Enumeración | C11: 1 | D11: 1 | E11: N/A | F11: N/A | G11: N/A | H11: Texto | I11: Activo | J11: No puede tener más de un estado simultáneo | K11: No | L11: No | M11: Sí | N11: No | O11: No | P11: Indica si el administrador puede iniciar sesión (Activo/Inactivo) | T11: Se cambia a Inactivo al desactivar la cuenta
A13: Combinaciones únicas
A14: Nombre combinación | B14: Descripción | C14: Atributos
A15: Cuenta única | B15: El NombreUsuario debe ser único en todo el sistema | C15: NombreUsuario
A16: Correo único | B16: El CorreoElectronico no puede repetirse entre administradores | C16: CorreoElectronico
A18: Responsabilidad | C18: Descripción | G18: Entradas | J18: Salida | O18: Políticas (Reglas de Negocio) | Q18: Excepción
G19: Parámetro | H19: Tipo de dato | I19: Descripción | J19: Tipo de Dato | K19: Descripción | O19: Política | P19: Descripción | Q19: Detalle | R19: ¿Qué hago?
A20: Registrar administrador | C20: Crea una nueva cuenta de administrador validando que los datos sean únicos y válidos. | G20: NombreUsuario, Contraseña, CorreoElectronico, Telefono | H20: Alfanumérico | I20: Datos digitados en el formulario de registro | J20: Objeto Administrador | K20: Cuenta creada con IdAdministrador asignado y Estado=Activo | O20: Solo administrador | P20: Únicamente otro administrador puede crear una cuenta nueva | Q20: El nombre de usuario o el correo ya está registrado | R20: Rechazar el registro y solicitar otro valor
A21: Autenticar administrador (Iniciar sesión) | C21: Valida las credenciales ingresadas para habilitar el acceso del administrador al sistema. | G21: NombreUsuario, Contraseña | H21: Alfanumérico | I21: Credenciales digitadas en el formulario de login | J21: Token de sesión | K21: Sesión activa asociada al IdAdministrador | O21: Máximo de intentos | P21: Bloquear intentos adicionales tras 5 intentos fallidos en 10 minutos | Q21: Administrador o contraseña incorrectos | R21: Mostrar un mensaje genérico de error sin revelar cuál dato falló
A22: Actualizar datos de administrador | C22: Modifica el correo, teléfono o contraseña de una cuenta existente. | G22: IdAdministrador, CampoAModificar, NuevoValor | H22: Numérico Entero, Texto, Texto | I22: Identificador de la cuenta y el dato a actualizar | J22: Objeto Administrador | K22: Cuenta con los datos actualizados | O22: Validación de formato | P22: Los nuevos datos deben cumplir las mismas reglas del registro | Q22: El nuevo dato no cumple el formato | R22: Rechazar el cambio y mantener el dato anterior
A23: Desactivar cuenta | C23: Cambia el Estado del administrador a Inactivo para impedir futuros inicios de sesión sin eliminar su historial. | G23: IdAdministrador | H23: Numérico Entero | I23: Cuenta a desactivar | J23: Objeto Administrador | K23: Cuenta con Estado=Inactivo | O23: Debe quedar al menos un administrador activo | P23: El sistema no permite desactivar al único administrador activo | Q23: Es el único administrador activo | R23: Impedir la desactivación hasta registrar otro administrador

Sheet Producto
A1: <-Volver al inicio
A2: Objeto de Dominio: | B2: ='Listado Objetos de Dominio'!$A$4 -> Producto
A3: Descripción: | B3: ='Listado Objetos de Dominio'!$B$4 -> Objeto de dominio que representa cada mueble de interior o exterior disponible para la venta en el catálogo.
A4: Atributo | B4: Tipo de Dato | C4: Longitud mínima | D4: Longitud máxima | E4: Precisión | F4: Rango Inicial | G4: Rango Final | H4: Formato | I4: Valor por defecto | J4: Regla especial | K4: ¿Auto generado? | L4: ¿Calculado? | M4: ¿Obligatorio? | N4: ¿Sensible? | O4: ¿Identifica al registro? | P4: Descripción | Q4: =A23 -> Publicar producto | R4: =A24 -> Actualizar producto o precio | S4: =A25 -> Consultar catálogo | T4: =A26 -> Descontinuar producto
A5: IdProducto | B5: Numérico Entero | C5: 1 | D5: 6 | E5: N/A | F5: 1 | G5: N/A | H5: Numérico | I5: N/A | J5: Único para cada producto; no se reutiliza | K5: Sí, por el propio sistema | L5: No | M5: Sí | N5: No | O5: Sí | P5: Identificador único del producto en el catálogo
A6: IdAlmacen | B6: Numérico Entero | C6: 1 | D6: 6 | E6: N/A | F6: 1 | G6: N/A | H6: Numérico | I6: Sin asignar | J6: Si se asigna, debe corresponder a un almacén existente | K6: No | L6: No | M6: No | N6: No | O6: No | P6: Almacén donde se exhibe este producto
A7: Nombre | B7: Alfanumérico | C7: 3 | D7: 100 | E7: N/A | F7: N/A | G7: N/A | H7: Texto | I7: N/A | J7: Debe describir claramente el mueble | K7: No | L7: No | M7: Sí | N7: No | O7: No | P7: Nombre comercial del producto | S7: Se compara contra el texto de búsqueda
A8: Categoria | B8: Enumeración | C8: 1 | D8: 1 | E8: N/A | F8: N/A | G8: N/A | H8: Texto | I8: N/A | J8: Debe ser una de las categorías habilitadas: Sillas, Comedores, Mesas, Mesas de Centro | K8: No | L8: No | M8: Sí | N8: No | O8: No | P8: Clasifica el producto dentro del catálogo | S8: Se usa como filtro de búsqueda
A9: Material | B9: Alfanumérico | C9: 3 | D9: 60 | E9: N/A | F9: N/A | G9: N/A | H9: Texto | I9: N/A | J9: Debe corresponder a materiales reales de fabricación de muebles | K9: No | L9: No | M9: Sí | N9: No | O9: No | P9: Material principal de fabricación del mueble
A10: Dimensiones | B10: Estructura | C10: 5 | D10: 40 | E10: N/A | F10: N/A | G10: N/A | H10: Alto x Ancho x Profundidad (cm) | I10: N/A | J10: Las tres medidas son obligatorias y mayores a 0 | K10: No | L10: No | M10: Sí | N10: No | O10: No | P10: Medidas físicas del producto en centímetros (ver detalle en el diagrama)
A11: Precio | B11: Numérico Entero | C11: 4 | D11: 9 | E11: N/A | F11: 1 | G11: N/A | H11: $ COP | I11: N/A | J11: Debe ser mayor a 0 y múltiplo de 100 | K11: No | L11: No | M11: Sí | N11: No | O11: No | P11: Precio de venta al público en pesos colombianos | Q11: Debe ser mayor a cero antes de publicar
A12: Stock | B12: Numérico Entero | C12: 1 | D12: 5 | E12: N/A | F12: 0 | G12: N/A | H12: Numérico | I12: 0 | J12: No puede ser negativo; se sincroniza con Bodega | K12: No | L12: Sí | M12: Sí | N12: No | O12: No | P12: Unidades disponibles para la venta en este momento | S12: Determina si el producto aparece como disponible
A13: Descripcion | B13: Alfanumérico | C13: 10 | D13: 500 | E13: N/A | F13: N/A | G13: N/A | H13: Texto | I13: Sin descripción adicional | J13: Debe describir características relevantes del producto | K13: No | L13: No | M13: No | N13: No | O13: No | P13: Texto descriptivo mostrado en la ficha del producto
A14: ImagenURL | B14: Alfanumérico | C14: 5 | D14: 250 | E14: N/A | F14: N/A | G14: N/A | H14: URL | I14: Sin imagen | J14: Debe apuntar a un archivo de imagen válido | K14: No | L14: No | M14: No | N14: No | O14: No | P14: Enlace a la imagen principal del producto
A15: Estado | B15: Enumeración | C15: 1 | D15: 1 | E15: N/A | F15: N/A | G15: N/A | H15: Texto | I15: Disponible | J15: No puede tener más de un estado simultáneo | K15: No | L15: Sí | M15: Sí | N15: No | O15: No | P15: Disponibilidad comercial del producto (Disponible/Agotado/Descontinuado) | S15: Los Descontinuados no aparecen en la búsqueda | T15: Se actualiza al descontinuar
A17: Combinaciones únicas
A18: Nombre combinación | B18: Descripción | C18: Atributos
A19: Identificador de producto | B19: No pueden existir dos productos con el mismo IdProducto | C19: IdProducto
A21: Responsabilidad | C21: Descripción | G21: Entradas | J21: Salida | O21: Políticas (Reglas de Negocio) | Q21: Excepción
G22: Parámetro | H22: Tipo de dato | I22: Descripción | J22: Tipo de Dato | K22: Descripción | O22: Política | P22: Descripción | Q22: Detalle | R22: ¿Qué hago?
A23: Publicar producto | C23: Registra un nuevo mueble en el catálogo junto con su stock inicial en Bodega. | G23: Nombre, Categoria, Ambiente, Material, Dimensiones, Precio, StockInicial | H23: Texto, Enum, Enum, Texto, Estructura, Numérico, Numérico | I23: Datos del producto digitados por el administrador | J23: Objeto Producto | K23: Producto creado con IdProducto asignado y Estado=Disponible | O23: Solo administrador | P23: Únicamente un Administrador puede publicar un producto nuevo en el catálogo | Q23: Falta un dato obligatorio | R23: Rechazar la publicación y señalar los campos incompletos
A24: Actualizar producto o precio | C24: Permite modificar los datos comerciales de un producto existente. | G24: IdProducto, CampoAModificar, NuevoValor | H24: Numérico Entero, Texto, Texto | I24: Producto a modificar y el nuevo valor | J24: Objeto Producto | K24: Producto con los datos actualizados | O24: Solo administrador | P24: Únicamente un administrador puede modificar productos | Q24: El producto no existe | R24: Informar que el IdProducto no fue encontrado
A25: Consultar catálogo | C25: Devuelve productos según texto de búsqueda, categoría o ambiente para mostrarlos en la tienda. | G25: TextoBusqueda, Categoria, Ambiente | H25: Texto, Enum, Enum | I25: Filtros opcionales digitados por el cliente en la barra de búsqueda | J25: Lista de Producto | K25: Productos que cumplen los filtros y están Disponibles | O25: Solo visibles | P25: Los productos Descontinuados no aparecen en la búsqueda | Q25: Ningún producto coincide con la búsqueda | R25: Devolver lista vacía y sugerir categorías relacionadas
A26: Descontinuar producto | C26: Retira un producto de la venta sin eliminar su historial de pedidos asociados. | G26: IdProducto | H26: Numérico Entero | I26: Producto a descontinuar | J26: Objeto Producto | K26: Producto con Estado=Descontinuado | O26: Conservar historial | P26: Los pedidos ya realizados con este producto no se ven afectados | Q26: El producto tiene stock disponible | R26: Advertir el stock restante y pedir confirmación antes de descontinuar

Sheet Almacén
A1: <-Volver al inicio
A2: Objeto de Dominio: | B2: ='Listado Objetos de Dominio'!$A$5 -> Almacén
A3: Descripción: | B3: ='Listado Objetos de Dominio'!$B$5 -> Objeto de dominio que representa el punto físico donde se exhiben los productos disponibles para la venta.
A4: Atributo | B4: Tipo de Dato | C4: Longitud mínima | D4: Longitud máxima | E4: Precisión | F4: Rango Inicial | G4: Rango Final | H4: Formato | I4: Valor por defecto | J4: Regla especial | K4: ¿Auto generado? | L4: ¿Calculado? | M4: ¿Obligatorio? | N4: ¿Sensible? | O4: ¿Identifica al registro? | P4: Descripción | Q4: =A18 -> Registrar almacén | R4: =A19 -> Actualizar datos del almacén | S4: =A20 -> Asignar producto a almacén | T4: =A21 -> Desactivar almacén
A5: IdAlmacen | B5: Numérico Entero | C5: 1 | D5: 6 | E5: N/A | F5: 1 | G5: N/A | H5: Numérico | I5: N/A | J5: Único por almacén | K5: Sí, por el propio sistema | L5: No | M5: Sí | N5: No | O5: Sí | P5: Identificador único del punto de exhibición
A6: Nombre | B6: Alfanumérico | C6: 3 | D6: 50 | E6: N/A | F6: N/A | G6: N/A | H6: Texto | I6: N/A | J6: N/A | K6: No | L6: No | M6: Sí | N6: No | O6: No | P6: Nombre con el que se identifica el almacén o showroom
A7: Direccion | B7: Alfanumérico | C7: 5 | D7: 100 | E7: N/A | F7: N/A | G7: N/A | H7: Texto | I7: N/A | J7: Debe ser una dirección real | K7: No | L7: No | M7: Sí | N7: No | O7: No | P7: Dirección física del almacén | Q7: Se descuenta al confirmar el pedido | R7: Se incrementa al reponer | T7: Se compara contra el umbral mínimo
A8: Ciudad | B8: Alfanumérico | C8: 3 | D8: 40 | E8: N/A | F8: N/A | G8: N/A | H8: Texto | I8: N/A | J8: N/A | K8: No | L8: No | M8: Sí | N8: No | O8: No | P8: Ciudad donde se ubica el almacén
A9: CapacidadExhibicion | B9: Numérico Entero | C9: 1 | D9: 5 | E9: N/A | F9: 0 | G9: N/A | H9: Numérico | I9: Sin límite definido | J9: No puede ser negativa | K9: No | L9: No | M9: No | N9: No | O9: No | P9: Cantidad máxima de productos que el almacén puede exhibir | S9: Se valida antes de asignar un nuevo producto
A10: Estado | B10: Enumeración | C10: 1 | D10: 1 | E10: N/A | F10: N/A | G10: N/A | H10: Texto | I10: Activo | J10: No puede tener más de un estado simultáneo | K10: No | L10: No | M10: Sí | N10: No | O10: No | P10: Indica si el almacén está operando actualmente | S10: Cambia a Pendiente si se pierde la conexión
A12: Combinaciones únicas
A13: Nombre combinación | B13: Descripción | C13: Atributos
A14: Nombre único | B14: El nombre del almacén no puede repetirse | C14: Nombre
A16: Responsabilidad | C16: Descripción | G16: Entradas | J16: Salida | O16: Políticas (Reglas de Negocio) | Q16: Excepción
G17: Parámetro | H17: Tipo de dato | I17: Descripción | J17: Tipo de Dato | K17: Descripción | O17: Política | P17: Descripción | Q17: Detalle | R17: ¿Qué hago?
A18: Registrar almacén | C18: Crea un nuevo punto físico de exhibición de productos. | G18: Nombre, Direccion, Ciudad, CapacidadExhibicion | H18: Alfanumérico Numérico Entero | I18: Datos del nuevo punto de exhibición | J18: Objeto Almacén | K18: Almacén creado con IdAlmacen asignado y Estado=Activo | O18: Solo administrador | P18: Únicamente un administrador puede registrar un almacén nuevo | Q18: El nombre ya está registrado | R18: Rechazar el registro y mostrar el almacén existente
A19: Actualizar datos del almacén | C19: Modifica dirección, ciudad o capacidad de un almacén existente. | G19: IdAlmacen, CampoAModificar, NuevoValor | H19: Numérico Entero, Texto | I19: Identificador del almacén y el dato a actualizar | J19: Objeto Almacén | K19: Almacén con los datos actualizados | O19: Solo administrador | P19: Únicamente un administrador puede modificar estos datos | Q19: El nuevo dato no cumple el formato | R19: Rechazar el cambio y mantener el dato anterior
A20: Asignar producto a almacén | C20: Vincula un producto disponible al punto de exhibición donde estará disponible al público. | G20: IdProducto, IdAlmacen | H20: Numérico Entero | I20: Producto a exhibir y almacén destino | J20: Objeto Producto | K20: Producto actualizado con el IdAlmacen asignado | O20: Capacidad disponible | P20: El almacén no puede exceder su CapacidadExhibicion | Q20: El almacén alcanzó su capacidad máxima | R20: Rechazar la asignación y notificar al administrador
A21: Desactivar almacén | C21: Cambia el Estado del almacén a Inactivo cuando deja de operar. | G21: IdAlmacen | H21: Numérico Entero | I21: Almacén a desactivar | J21: Objeto Almacén | K21: Almacén con Estado=Inactivo | O21: Sin productos activos | P21: El almacén no puede desactivarse si aún exhibe productos | Q21: El almacén todavía tiene productos exhibidos activos | R21: Reasignar los productos a otro almacén antes de desactivar

Sheet Carrito
A1: <-Volver al inicio
A2: Objeto de Dominio: | B2: ='Listado Objetos de Dominio'!$A$6 -> Carrito
A3: Descripción: | B3: ='Listado Objetos de Dominio'!$B$6 -> Objeto de dominio que representa la selección temporal de productos que se arma antes de confirmar la compra.
A4: Atributo | B4: Tipo de Dato | C4: Longitud mínima | D4: Longitud máxima | E4: Precisión | F4: Rango Inicial | G4: Rango Final | H4: Formato | I4: Valor por defecto | J4: Regla especial | K4: ¿Auto generado? | L4: ¿Calculado? | M4: ¿Obligatorio? | N4: ¿Sensible? | O4: ¿Identifica al registro? | P4: Descripción | Q4: =A17 -> Agregar producto al carrito | R4: =A18 -> Actualizar o eliminar producto del carrito | S4: =A19 -> Confirmar compra (checkout) | T4: =A20 -> Vaciar carrito
A5: IdCarrito | B5: Numérico Entero | C5: 1 | D5: 6 | E5: N/A | F5: 1 | G5: N/A | H5: Numérico | I5: N/A | J5: Único por carrito activo | K5: Sí, por el propio sistema | L5: No | M5: Sí | N5: No | O5: Sí | P5: Identificador único del carrito
A6: IdVendedor | B6: Numérico Entero | C6: 1 | D6: 6 | E6: N/A | F6: 1 | G6: N/A | H6: Numérico | I6: Sin asignar | J6: Si se asigna, debe corresponder a un vendedor existente | K6: No | L6: No | M6: No | N6: No | O6: No | P6: Vendedor que gestiona este carrito
A7: FechaCreacion | B7: Fecha | C7: 10 | D7: 10 | E7: N/A | F7: N/A | G7: Fecha actual | H7: dd/mm/aaaa | I7: Fecha actual | J7: Debe ser igual o anterior a la fecha del sistema | K7: Sí | L7: No | M7: Sí | N7: No | O7: No | P7: Momento en que se creó el carrito
A8: Estado | B8: Enumeración | C8: 1 | D8: 1 | E8: N/A | F8: N/A | G8: N/A | H8: Texto | I8: Activo | J8: No puede tener más de un estado simultáneo | K8: No | L8: No | M8: Sí | N8: No | O8: No | P8: Situación actual del carrito (Activo/Convertido/Abandonado) | T8: Se marca como Abandonado si no se retoma
A9: TotalEstimado | B9: Numérico Entero | C9: 1 | D9: 9 | E9: N/A | F9: 0 | G9: N/A | H9: $ COP | I9: 0 | J9: Debe ser igual a la suma de (precio x cantidad) de cada producto | K9: No | L9: Sí | M9: Sí | N9: No | O9: No | P9: Valor aproximado de la compra antes de confirmarla
A11: Combinaciones únicas
A12: Nombre combinación | B12: Descripción | C12: Atributos
A13: Carrito activo por vendedor | B13: Un vendedor no puede tener más de un carrito en estado Activo al mismo tiempo | C13: IdVendedor, Estado
A15: Responsabilidad | C15: Descripción | G15: Entradas | J15: Salida | O15: Políticas (Reglas de Negocio) | Q15: Excepción
G16: Parámetro | H16: Tipo de dato | I16: Descripción | J16: Tipo de Dato | K16: Descripción | O16: Política | P16: Descripción | Q16: Detalle | R16: ¿Qué hago?
A17: Agregar producto al carrito | C17: Incluye un producto y una cantidad en el carrito, agrupando la cantidad si el producto ya estaba agregado. | G17: IdCarrito, IdProducto, Cantidad | H17: Numérico Entero | I17: Producto y cantidad que el cliente quiere agregar | J17: Objeto Carrito | K17: Carrito actualizado con el nuevo total estimado | O17: Agrupar cantidades | P17: Si el producto ya existe en el carrito, sumar la cantidad en vez de crear otra línea | Q17: No hay stock suficiente para la cantidad pedida | R17: Ajustar la cantidad al máximo disponible y notificar al cliente
A18: Actualizar o eliminar producto del carrito | C18: Cambia la cantidad de un producto ya agregado o lo retira por completo del carrito. | G18: IdCarrito, IdProducto, NuevaCantidad | H18: Numérico Entero | I18: Producto a modificar y su nueva cantidad (0 para eliminar) | J18: Objeto Carrito | K18: Carrito con el listado y total actualizados | O18: Cantidad mínima | P18: Una cantidad de 0 elimina el producto del carrito | Q18: El producto no está en el carrito | R18: Informar que no hay nada que actualizar
A19: Confirmar compra (checkout) | C19: Convierte el carrito activo en un Pedido formal y lo deja disponible para el pago. | G19: IdCarrito, DireccionEntrega | H19: Numérico Entero, Texto | I19: Carrito a confirmar y dirección de entrega | J19: Objeto Pedido | K19: Pedido nuevo en estado Pendiente de pago | O19: Carrito no vacío | P19: El carrito debe tener al menos un producto para confirmar la compra | Q19: El carrito está vacío | R19: Impedir el checkout y regresar al cliente al catálogo
A20: Vaciar carrito | C20: Elimina todos los productos del carrito activo, marcándolo como abandonado si no se retoma. | G20: IdCarrito | H20: Numérico Entero | I20: Carrito a vaciar | J20: Objeto Carrito | K20: Carrito sin productos y total en cero | O20: Registro para analítica | P20: Se conserva la fecha del último vaciado para análisis de abandono | Q20: El carrito ya estaba vacío | R20: No aplicar ninguna acción adicional

Sheet Pedido
A1: <-Volver al inicio
A2: Objeto de Dominio: | B2: ='Listado Objetos de Dominio'!$A$7 -> Pedido
A3: Descripción: | B3: ='Listado Objetos de Dominio'!$B$7 -> Objeto de dominio que representa una compra confirmada, desde su creación hasta la entrega.
A4: Atributo | B4: Tipo de Dato | C4: Longitud mínima | D4: Longitud máxima | E4: Precisión | F4: Rango Inicial | G4: Rango Final | H4: Formato | I4: Valor por defecto | J4: Regla especial | K4: ¿Auto generado? | L4: ¿Calculado? | M4: ¿Obligatorio? | N4: ¿Sensible? | O4: ¿Identifica al registro? | P4: Descripción | Q4: =A22 -> Crear pedido desde carrito | R4: =A23 -> Actualizar estado del pedido | S4: =A24 -> Generar comprobante de pedido | T4: =A25 -> Registrar pedido personalizado
A5: IdPedido | B5: Numérico Entero | C5: 1 | D5: 6 | E5: N/A | F5: 1 | G5: N/A | H5: Numérico | I5: N/A | J5: Único para cada pedido; no se reutiliza | K5: Sí, por el propio sistema | L5: No | M5: Sí | N5: No | O5: Sí | P5: Identificador único del pedido
A6: IdVendedor | B6: Numérico Entero | C6: 1 | D6: 6 | E6: N/A | F6: 1 | G6: N/A | H6: Numérico | I6: N/A | J6: Debe corresponder a un vendedor existente | K6: No | L6: No | M6: Sí | N6: No | O6: No | P6: Vendedor que gestionó el pedido
A7: FechaPedido | B7: Fecha | C7: 10 | D7: 10 | E7: N/A | F7: N/A | G7: Fecha actual | H7: dd/mm/aaaa | I7: Fecha actual | J7: Debe ser igual o anterior a la fecha del sistema | K7: Sí | L7: No | M7: Sí | N7: No | O7: No | P7: Fecha en la que se confirmó el pedido
A8: Origen | B8: Enumeración | C8: 1 | D8: 1 | E8: N/A | F8: N/A | G8: N/A | H8: Texto | I8: Catálogo web | J8: Debe ser Catálogo web o Personalizado (Instagram) | K8: No | L8: No | M8: Sí | N8: No | O8: No | P8: Canal por el cual se originó el pedido | T8: Se fija en Personalizado para solicitudes externas
A9: Estado | B9: Enumeración | C9: 1 | D9: 1 | E9: N/A | F9: N/A | G9: N/A | H9: Texto | I9: Pendiente | J9: Solo un estado a la vez; sigue la secuencia Pendiente-Pagado-Enviado-Entregado | K9: No | L9: Sí | M9: Sí | N9: No | O9: No | P9: Etapa actual del pedido dentro de su ciclo de vida | R9: Avanza según la secuencia permitida | S9: Debe ser Pagado para emitir comprobante
A10: MontoTotal | B10: Numérico Entero | C10: 4 | D10: 9 | E10: N/A | F10: 1 | G10: N/A | H10: $ COP | I10: N/A | J10: Igual a la suma de (PrecioUnitario x Cantidad) de cada producto | K10: No | L10: Sí | M10: Sí | N10: No | O10: No | P10: Valor total a pagar por el pedido
A11: DireccionEntrega | B11: Alfanumérico | C11: 10 | D11: 200 | E11: N/A | F11: N/A | G11: N/A | H11: Texto | I11: Recoge en almacén | J11: Obligatoria únicamente si el pedido es a domicilio | K11: No | L11: No | M11: No | N11: Sí | O11: No | P11: Lugar donde se entregará el pedido
A12: IdCliente | B12: Numérico Entero | C12: 1 | D12: 6 | E12: N/A | F12: 1 | G12: N/A | H12: Numérico | I12: N/A | J12: Debe corresponder a un cliente existente; si no existe, se registra antes de asociarlo al pedido | K12: No | L12: No | M12: Sí | N12: No | O12: No | P12: Cliente para quien se realiza el pedido
A13: Ciudad | B13: Alfanumérico | C13: 3 | D13: 40 | E13: N/A | F13: N/A | G13: N/A | H13: Texto | I13: N/A | J13: N/A | K13: No | L13: No | M13: Sí | N13: No | O13: No | P13: Ciudad de entrega del pedido
A14: Notas | B14: Alfanumérico | C14: 0 | D14: 300 | E14: N/A | F14: N/A | G14: N/A | H14: Texto | I14: N/A | J14: N/A | K14: No | L14: No | M14: No | N14: No | O14: No | P14: Instrucciones adicionales de entrega, referencias del lugar (opcional)
A16: Combinaciones únicas
A17: Nombre combinación | B17: Descripción | C17: Atributos
A18: Identificador de pedido | B18: No pueden existir dos pedidos con el mismo IdPedido | C18: IdPedido
A20: Responsabilidad | C20: Descripción | G20: Entradas | J20: Salida | O20: Políticas (Reglas de Negocio) | Q20: Excepción
G21: Parámetro | H21: Tipo de dato | I21: Descripción | J21: Tipo de Dato | K21: Descripción | O21: Política | P21: Descripción | Q21: Detalle | R21: ¿Qué hago?
A22: Crear pedido desde carrito | C22: Genera el pedido formal a partir de un carrito confirmado, copiando productos y precios vigentes. | G22: IdCarrito, DireccionEntrega | H22: Numérico Entero, Texto | I22: Carrito de origen y dirección de entrega | J22: Objeto Pedido | K22: Pedido creado en estado Pendiente | O22: Precio congelado | P22: El MontoTotal se calcula con los precios del catálogo al momento de crear el pedido | Q22: Un producto del carrito ya no está disponible | R22: Retirarlo del pedido y notificar al cliente antes de continuar
A23: Actualizar estado del pedido | C23: Avanza el pedido a través de su ciclo de vida conforme se confirma el pago y el envío. | G23: IdPedido, NuevoEstado | H23: Numérico Entero, Enumeración | I23: Pedido y el nuevo estado a asignar | J23: Objeto Pedido | K23: Pedido con el estado actualizado | O23: Secuencia válida | P23: El estado solo avanza en el orden Pendiente-Pagado-Enviado-Entregado, o pasa a Cancelado | Q23: Se intenta un cambio de estado fuera de secuencia | R23: Rechazar el cambio y mantener el estado actual
A24: Generar comprobante de pedido | C24: Produce el recibo imprimible o descargable con el detalle del pedido y su pago. | G24: IdPedido | H24: Numérico Entero | I24: Pedido del cual se solicita el comprobante | J24: Documento PDF | K24: Comprobante con productos, montos y datos del cliente | O24: Solo pedidos pagados | P24: El comprobante solo se genera si el pedido tiene un Pago en estado Aprobado | Q24: El pedido aún no ha sido pagado | R24: Informar que el comprobante estará disponible tras aprobar el pago
A25: Registrar pedido personalizado | C25: Crea un pedido con Origen=Personalizado a partir de una solicitud recibida por Instagram u otro canal externo. | G25: IdVendedor, DetalleSolicitud, DireccionEntrega | H25: Numérico Entero, Texto, Texto | I25: Vendedor que atiende la solicitud y descripción del mueble personalizado pedido por el cliente | J25: Objeto Pedido | K25: Pedido en estado Pendiente con Origen=Personalizado | O25: Validación manual | P25: Un administrador debe confirmar precio y tiempo de entrega antes de habilitar el pago | Q25: El administrador no confirma la solicitud | R25: Mantener el pedido en Pendiente y notificar al cliente por el mismo canal

Sheet Pago
A1: <-Volver al inicio
A2: Objeto de Dominio: | B2: ='Listado Objetos de Dominio'!$A$8 -> Pago
A3: Descripción: | B3: ='Listado Objetos de Dominio'!$B$8 -> Objeto de dominio que representa la transacción mediante la cual se cubre el valor de un pedido.
A4: Atributo | B4: Tipo de Dato | C4: Longitud mínima | D4: Longitud máxima | E4: Precisión | F4: Rango Inicial | G4: Rango Final | H4: Formato | I4: Valor por defecto | J4: Regla especial | K4: ¿Auto generado? | L4: ¿Calculado? | M4: ¿Obligatorio? | N4: ¿Sensible? | O4: ¿Identifica al registro? | P4: Descripción | Q4: =A18 -> Registrar pago | R4: =A19 -> Actualizar estado del pago | S4: =A20 -> Consultar historial de pagos | T4: =A21 -> Anular pago
A5: IdPago | B5: Numérico Entero | C5: 1 | D5: 6 | E5: N/A | F5: 1 | G5: N/A | H5: Numérico | I5: N/A | J5: Único por pago | K5: Sí, por el propio sistema | L5: No | M5: Sí | N5: No | O5: Sí | P5: Identificador único de la transacción de pago
A6: IdPedido | B6: Numérico Entero | C6: 1 | D6: 6 | E6: N/A | F6: 1 | G6: N/A | H6: Numérico | I6: N/A | J6: Debe corresponder a un pedido existente; un pedido puede tener varios pagos (adelanto + abonos) | K6: No | L6: No | M6: Sí | N6: No | O6: Sí | P6: Pedido al que corresponde este pago (un pedido puede acumular varios)
A7: Monto | B7: Numérico Entero | C7: 1 | D7: 10 | E7: N/A | F7: 0 | G7: N/A | H7: $ COP | I7: N/A | J7: Puede ser igual al MontoTotal del pedido, o un abono parcial; la suma de los pagos de un pedido no puede superar el MontoTotal | K7: No | L7: Sí | M7: Sí | N7: No | O7: No | P7: Valor cubierto en este pago puntual (puede ser un adelanto) | Q7: Se descuenta al confirmar el pedido | R7: Se incrementa al reponer | T7: Se compara contra el umbral mínimo
A8: MetodoPago | B8: Enumeración | C8: 1 | D8: 1 | E8: N/A | F8: N/A | G8: N/A | H8: Texto | I8: N/A | J8: No puede tener más de un método simultáneo | K8: No | L8: No | M8: Sí | N8: No | O8: No | P8: Medio utilizado para pagar: Efectivo, Datáfono o Transferencia
A9: FechaPago | B9: Fecha | C9: 16 | D9: 16 | E9: N/A | F9: N/A | G9: Fecha y hora actual | H9: dd/mm/aaaa hh:mm | I9: Fecha y hora actual | J9: Se registra automáticamente al aprobarse | K9: Sí | L9: Sí | M9: Sí | N9: Si | O9: No | P9: Momento en que se procesó el pago | S9: Se refresca en cada sincronización
A10: Estado | B10: Enumeración | C10: 1 | D10: 1 | E10: N/A | F10: N/A | G10: N/A | H10: Texto | I10: Pendiente | J10: No puede tener más de un estado simultáneo | K10: No | L10: Sí | M10: Sí | N10: No | O10: No | P10: Indica si el pago está Pendiente, Aprobado o Rechazado | S10: Cambia a Pendiente si se pierde la conexión | T10: Un Estado=Aprobado descuenta stock en Bodega y habilita el comprobante del pedido
A12: Combinaciones únicas
A13: Nombre combinación | B13: Descripción | C13: Atributos
A14: Pago dentro del monto del pedido | B14: La suma de los pagos de un mismo IdPedido no puede superar su MontoTotal | C14: IdPedido, Monto
A16: Responsabilidad | C16: Descripción | G16: Entradas | J16: Salida | O16: Políticas (Reglas de Negocio) | Q16: Excepción
G17: Parámetro | H17: Tipo de dato | I17: Descripción | J17: Tipo de Dato | K17: Descripción | O17: Política | P17: Descripción | Q17: Detalle | R17: ¿Qué hago?
A18: Registrar pago | C18: Crea el registro de pago asociado a un pedido confirmado. | G18: IdPedido, Monto, MetodoPago | H18: Numérico Entero, Enumeración | I18: Pedido a pagar, valor y medio de pago elegido | J18: Objeto Pago | K18: Pago creado en estado Pendiente | O18: Monto exacto | P18: El Monto debe ser igual al MontoTotal del pedido | Q18: El monto no coincide | R18: Rechazar el registro y solicitar el valor correcto
A19: Actualizar estado del pago | C19: Aprueba o rechaza la transacción según la respuesta del medio de pago. | G19: IdPago, NuevoEstado | H19: Numérico Entero, Enumeración | I19: Pago a actualizar y resultado de la transacción | J19: Objeto Pago | K19: Pago con el estado actualizado | O19: Descuenta stock al aprobar | P19: Un pago Aprobado dispara el descuento de stock en Bodega | Q19: El pago es rechazado | R19: Mantener el pedido en estado Pendiente y notificar al cliente
A20: Consultar historial de pagos | C20: Permite revisar los pagos registrados por pedido, fecha o estado. | G20: IdPedido o rango de fechas | H20: Texto | I20: Filtros de búsqueda | J20: Lista de objetos Pago | K20: Pagos que coinciden con el filtro | O20: Solo administrador | P20: Únicamente un administrador puede consultar el historial completo | Q20: No hay pagos que coincidan | R20: Mostrar un mensaje de "sin resultados"
A21: Anular pago | C21: Revierte un pago Aprobado en caso de cancelación o reembolso. | G21: IdPago | H21: Numérico Entero | I21: Pago a anular | J21: Objeto Pago | K21: Pago en estado Rechazado | O21: Solo antes del envío | P21: Un pago no se puede anular si el pedido ya fue enviado | Q21: El pedido ya está en estado Enviado | R21: Bloquear la anulación e indicar que se gestiona como devolución

Sheet Bodega
A1: <-Volver al inicio
A2: Objeto de Dominio: | B2: ='Listado Objetos de Dominio'!$A$9 -> Bodega
A3: Descripción: | B3: ='Listado Objetos de Dominio'!$B$9 -> Objeto de dominio que representa el control de existencias físicas de cada producto y su sincronización con la tienda.
A4: Atributo | B4: Tipo de Dato | C4: Longitud mínima | D4: Longitud máxima | E4: Precisión | F4: Rango Inicial | G4: Rango Final | H4: Formato | I4: Valor por defecto | J4: Regla especial | K4: ¿Auto generado? | L4: ¿Calculado? | M4: ¿Obligatorio? | N4: ¿Sensible? | O4: ¿Identifica al registro? | P4: Descripción | Q4: =A18 -> Descontar stock al confirmar pedido | R4: =A19 -> Reponer stock | S4: =A20 -> Sincronizar bodega física con la tienda | T4: =A21 -> Alertar bajo stock
A5: IdBodega | B5: Numérico Entero | C5: 1 | D5: 6 | E5: N/A | F5: 1 | G5: N/A | H5: Numérico | I5: N/A | J5: Único por registro de bodega | K5: Sí, por el propio sistema | L5: No | M5: Sí | N5: No | O5: Sí | P5: Identificador único del registro de inventario
A6: IdProducto | B6: Numérico Entero | C6: 1 | D6: 6 | E6: N/A | F6: 1 | G6: N/A | H6: Numérico | I6: N/A | J6: Debe corresponder a un producto existente; un producto tiene un único registro de bodega | K6: No | L6: No | M6: Sí | N6: No | O6: Sí | P6: Producto al que pertenece este registro de inventario
A7: CantidadDisponible | B7: Numérico Entero | C7: 1 | D7: 5 | E7: N/A | F7: 0 | G7: N/A | H7: Numérico | I7: 0 | J7: No puede ser negativa | K7: No | L7: Sí | M7: Sí | N7: No | O7: No | P7: Unidades físicas actualmente disponibles para la venta | Q7: Se descuenta al confirmar el pedido | R7: Se incrementa al reponer | T7: Se compara contra el umbral mínimo
A8: Ubicacion | B8: Alfanumérico | C8: 3 | D8: 60 | E8: N/A | F8: N/A | G8: N/A | H8: Texto | I8: Sin ubicar | J8: Debe corresponder a una zona real de la bodega | K8: No | L8: No | M8: No | N8: No | O8: No | P8: Zona o estante físico donde se almacena el producto
A9: UltimaActualizacion | B9: Fecha | C9: 16 | D9: 16 | E9: N/A | F9: N/A | G9: Fecha y hora actual | H9: dd/mm/aaaa hh:mm | I9: Fecha y hora actual | J9: Se actualiza automáticamente ante cualquier cambio de cantidad | K9: Sí | L9: Sí | M9: Sí | N9: No | O9: No | P9: Momento del último cambio registrado en el inventario | S9: Se refresca en cada sincronización
A10: EstadoSincronizacion | B10: Enumeración | C10: 1 | D10: 1 | E10: N/A | F10: N/A | G10: N/A | H10: Texto | I10: Sincronizado | J10: No puede tener más de un estado simultáneo | K10: No | L10: Sí | M10: Sí | N10: No | O10: No | P10: Indica si el dato coincide con la bodega física en tiempo real | S10: Cambia a Pendiente si se pierde la conexión
A12: Combinaciones únicas
A13: Nombre combinación | B13: Descripción | C13: Atributos
A14: Un registro por producto | B14: Un producto no puede tener más de un registro activo de bodega | C14: IdProducto
A16: Responsabilidad | C16: Descripción | G16: Entradas | J16: Salida | O16: Políticas (Reglas de Negocio) | Q16: Excepción
G17: Parámetro | H17: Tipo de dato | I17: Descripción | J17: Tipo de Dato | K17: Descripción | O17: Política | P17: Descripción | Q17: Detalle | R17: ¿Qué hago?
A18: Descontar stock al confirmar pedido | C18: Reduce la CantidadDisponible de cada producto cuando un pago queda Aprobado. | G18: IdProducto, Cantidad | H18: Numérico Entero | I18: Producto y cantidad vendida en el pedido pagado | J18: Objeto Bodega | K18: Registro de bodega con la nueva CantidadDisponible | O18: Sin stock negativo | P18: La cantidad nunca puede quedar por debajo de cero | Q18: La cantidad solicitada supera el stock disponible | R18: Bloquear la confirmación del pedido y notificar al cliente antes de cobrar
A19: Reponer stock | C19: Aumenta la CantidadDisponible cuando llega nueva mercancía a la bodega. | G19: IdProducto, CantidadIngresada | H19: Numérico Enteroo | I19: Producto y unidades que ingresan a bodega | J19: Objeto Bodega | K19: Registro de bodega con la cantidad incrementada | O19: Solo personal autorizado | P19: Únicamente un administrador puede registrar reposiciones | Q19: El producto no tiene registro previo en bodega | R19: Crear el registro de bodega antes de aplicar la reposición
A20: Sincronizar bodega física con la tienda | C20: Actualiza en tiempo real la cantidad disponible mostrada en la tienda cuando cambia el inventario físico. | G20: IdProducto, CantidadActual | H20: Numérico Entero | I20: Lectura enviada desde bodega mediante WebSockets | J20: Objeto Bodega | K20: Registro con EstadoSincronizacion=Sincronizado y hora actualizada | O20: Actualización inmediata | P20: La tienda debe reflejar el cambio sin necesidad de recargar la página | Q20: Se pierde la conexión con bodega | R20: Marcar EstadoSincronizacion=Pendiente y mostrar el último dato conocido
A21: Alertar bajo stock | C21: Notifica al administrador cuando la cantidad disponible de un producto baja de un umbral mínimo. | G21: IdProducto, UmbralMinimo | H21: Numérico Entero | I21: Producto a vigilar y cantidad mínima aceptable | J21: Notificación | K21: Aviso enviado al administrador con el producto y cantidad restante | O21: Umbral configurable | P21: Cada producto puede tener su propio umbral mínimo de alerta | Q21: El producto llega a cantidad cero | R21: Cambiar automáticamente el Estado del producto a Agotado

Sheet Envío
A1: <-Volver al inicio
A2: Objeto de Dominio: | B2: ='Listado Objetos de Dominio'!$A$10 -> Envío
A3: Descripción: | B3: ='Listado Objetos de Dominio'!$B$10 -> Objeto de dominio que representa el proceso de transporte y entrega de un pedido confirmado al cliente.
A4: Atributo | B4: Tipo de Dato | C4: Longitud mínima | D4: Longitud máxima | E4: Precisión | F4: Rango Inicial | G4: Rango Final | H4: Formato | I4: Valor por defecto | J4: Regla especial | K4: ¿Auto generado? | L4: ¿Calculado? | M4: ¿Obligatorio? | N4: ¿Sensible? | O4: ¿Identifica al registro? | P4: Descripción | Q4: =A19 -> Registrar envío | R4: =A20 -> Actualizar estado de envío | S4: =A21 -> Consultar seguimiento | T4: =A22 -> Confirmar entrega
A5: IdEnvio | B5: Numérico Entero | C5: 1 | D5: 6 | E5: N/A | F5: 1 | G5: N/A | H5: Numérico | I5: N/A | J5: Único por envío | K5: Sí, por el propio sistema | L5: No | M5: Sí | N5: No | O5: Sí | P5: Identificador único del envío
A6: IdPedido | B6: Numérico Entero | C6: 1 | D6: 6 | E6: N/A | F6: 1 | G6: N/A | H6: Numérico | I6: N/A | J6: Debe corresponder a un pedido existente; un pedido tiene un único envío | K6: No | L6: No | M6: Sí | N6: No | O6: Sí | P6: Pedido que se está transportando | R6: Solo el propietario puede eliminarla
A7: IdAdministrador | B7: Numérico Entero | C7: 1 | D7: 6 | E7: N/A | F7: 1 | G7: N/A | H7: Numérico | I7: N/A | J7: Debe corresponder a un administrador existente | K7: No | L7: No | M7: Sí | N7: No | O7: No | P7: Administrador que gestiona el envío | Q7: Debe tener 16 dígitos válidos | T7: Se enmascara en cualquier pantalla
A8: Transportadora | B8: Alfanumérico | C8: 3 | D8: 40 | E8: N/A | F8: N/A | G8: N/A | H8: Texto | I8: Pendiente de asignar | J8: N/A | K8: No | L8: No | M8: No | N8: No | O8: No | P8: Empresa encargada de transportar el pedido
A9: NumeroGuia | B9: Alfanumérico | C9: 5 | D9: 30 | E9: N/A | F9: N/A | G9: N/A | H9: Texto | I9: Pendiente de asignar | J9: Único por envío | K9: Sí, por la transportadora | L9: No | M9: No | N9: No | O9: No | P9: Código de rastreo asignado por la transportadora | Q9: Debe ser futura para poder registrarse | S9: Se valida antes de seleccionarla
A10: FechaEnvio | B10: Fecha | C10: 10 | D10: 10 | E10: N/A | F10: N/A | G10: Fecha actual | H10: dd/mm/aaaa | I10: Pendiente (aún no ha salido) | J10: No puede ser anterior a la fecha del pedido | K10: No | L10: No | M10: No | N10: No | O10: No | P10: Fecha en que el pedido salió hacia su destino
A11: Estado | B11: Enumeración | C11: 1 | D11: 1 | E11: N/A | F11: N/A | G11: N/A | H11: Texto | I11: Preparando | J11: No puede tener más de un estado simultáneo | K11: No | L11: No | M11: Sí | N11: No | O11: No | P11: Indica si el envío está Preparando, En tránsito o Entregado | T11: Al llegar a Entregado, el Pedido asociado cambia también a Entregado
A13: Combinaciones únicas
A14: Nombre combinación | B14: Descripción | C14: Atributos
A15: Envío único por pedido | B15: Un pedido no puede tener más de un envío asociado | C15: IdPedido
A17: Responsabilidad | C17: Descripción | G17: Entradas | J17: Salida | O17: Políticas (Reglas de Negocio) | Q17: Excepción
G18: Parámetro | H18: Tipo de dato | I18: Descripción | J18: Tipo de Dato | K18: Descripción | O18: Política | P18: Descripción | Q18: Detalle | R18: ¿Qué hago?
A19: Registrar envío | C19: Crea el envío para un pedido con pago aprobado. | G19: IdPedido, IdAdministrador, Transportadora | H19: Numérico Entero, Alfanumérico | I19: Pedido a enviar, administrador responsable y transportadora asignada | J19: Objeto Envío | K19: Envío creado en estado Preparando | O19: Solo administrador y pago aprobado | P19: Únicamente un Administrador puede registrar el envío, y solo si el pedido cuenta con un Pago en estado Aprobado | Q19: El pedido no tiene un pago aprobado | R19: Rechazar el registro del envío
A20: Actualizar estado de envío | C20: Cambia el Estado conforme avanza el transporte del pedido. | G20: IdEnvio, NuevoEstado | H20: Numérico Entero, Enumeración | I20: Envío a actualizar y nuevo estado | J20: Objeto Envío | K20: Envío con el estado actualizado | O20: Solo administrador | P20: Únicamente un administrador puede actualizar el estado | Q20: Se intenta retroceder el estado | R20: Bloquear el cambio y mantener el estado actual
A21: Consultar seguimiento | C21: Permite verificar el estado y número de guía de un envío. | G21: IdPedido o NumeroGuia | H21: Texto | I21: Dato de búsqueda proporcionado por el cliente | J21: Objeto Envío | K21: Estado actual y número de guía del envío | O21: Acceso abierto | P21: El cliente puede consultar el seguimiento sin autenticarse | Q21: No existe un envío para ese pedido | R21: Mostrar un mensaje de "envío no encontrado"
A22: Confirmar entrega | C22: Marca el envío como Entregado cuando el pedido llega a su destino. | G22: IdEnvio | H22: Numérico Entero | I22: Envío a marcar como entregado | J22: Objeto Envío + Objeto Pedido | K22: Envío con Estado=Entregado y Pedido con Estado=Entregado | O22: Actualiza el pedido | P22: Al confirmar la entrega, el Pedido asociado también cambia a Entregado | Q22: El envío no está en tránsito | R22: Impedir marcar como entregado un envío que no ha salido

Sheet Cliente
A1: <-Volver al inicio
A2: Objeto de Dominio: | B2: ='Listado Objetos de Dominio'!$A$11 -> Cliente
A3: Descripción: | B3: ='Listado Objetos de Dominio'!$B$11 -> Objeto de dominio que representa a la persona para quien se realiza un pedido, identificada por su teléfono.
A4: Atributo | B4: Tipo de Dato | C4: Longitud mínima | D4: Longitud máxima | E4: Precisión | F4: Rango Inicial | G4: Rango Final | H4: Formato | I4: Valor por defecto | J4: Regla especial | K4: ¿Auto generado? | L4: ¿Calculado? | M4: ¿Obligatorio? | N4: ¿Sensible? | O4: ¿Identifica al registro? | P4: Descripción | Q4: =A18 -> Registrar cliente | R4: =A19 -> Actualizar datos del cliente | S4: =A20 -> Consultar historial de pedidos del cliente | T4: =A21 -> Consultar clientes frecuentes
A5: IdCliente | B5: Numérico Entero | C5: 1 | D5: 6 | E5: N/A | F5: 1 | G5: N/A | H5: Numérico | I5: N/A | J5: Único para cada cliente; no se reutiliza | K5: Sí, por el propio sistema | L5: No | M5: Sí | N5: No | O5: Sí | P5: Identificador único del cliente
A6: Nombre | B6: Alfanumérico | C6: 3 | D6: 80 | E6: N/A | F6: N/A | G6: N/A | H6: Texto | I6: N/A | J6: N/A | K6: No | L6: No | M6: Sí | N6: No | O6: No | P6: Nombre completo de la persona a la que se le vende
A7: Telefono | B7: Alfanumérico | C7: 7 | D7: 15 | E7: N/A | F7: N/A | G7: N/A | H7: Texto | I7: N/A | J7: Se usa para identificar si el cliente ya existe | K7: No | L7: No | M7: Sí | N7: Sí | O7: No | P7: Número de contacto del cliente; funciona como su llave natural de negocio
A8: Ciudad | B8: Alfanumérico | C8: 3 | D8: 40 | E8: N/A | F8: N/A | G8: N/A | H8: Texto | I8: N/A | J8: N/A | K8: No | L8: No | M8: No | N8: No | O8: No | P8: Ciudad habitual del cliente (referencia; el pedido puede entregarse en otra)
A9: FechaRegistro | B9: Fecha | C9: 10 | D9: 10 | E9: N/A | F9: N/A | G9: Fecha actual | H9: dd/mm/aaaa | I9: Fecha actual | J9: Debe ser igual o anterior a la fecha del sistema | K9: Sí | L9: No | M9: Sí | N9: No | O9: No | P9: Fecha en que el cliente quedó registrado por primera vez
A10: TotalPedidos | B10: Numérico Entero | C10: 1 | D10: 6 | E10: N/A | F10: 0 | G10: N/A | H10: Numérico | I10: 0 | J10: Se recalcula cada vez que el cliente completa un nuevo pedido | K10: No | L10: Sí | M10: Sí | N10: No | O10: No | P10: Cantidad de pedidos históricos del cliente; identifica clientes frecuentes
A12: Combinaciones únicas
A13: Nombre combinación | B13: Descripción | C13: Atributos
A14: Teléfono único | B14: Un cliente no puede repetirse con el mismo teléfono | C14: Telefono
A16: Responsabilidad | C16: Descripción | G16: Entradas | J16: Salida | O16: Políticas (Reglas de Negocio) | Q16: Excepción
G17: Parámetro | H17: Tipo de dato | I17: Descripción | J17: Tipo de Dato | K17: Descripción | O17: Política | P17: Descripción | Q17: Detalle | R17: ¿Qué hago?
A18: Registrar cliente | C18: Busca un cliente por Teléfono; si no existe, lo crea antes de asociarlo a un pedido. | G18: Nombre, Telefono | H18: Alfanumérico | I18: Datos del cliente proporcionados al momento de la venta | J18: Objeto Cliente | K18: Cliente existente o recién creado | O18: Teléfono como llave | P18: La búsqueda de coincidencia se hace siempre por Teléfono, nunca por Nombre | Q18: El teléfono ya existe con un nombre distinto | R18: Preguntar si es la misma persona antes de sobrescribir el nombre
A19: Actualizar datos del cliente | C19: Corrige nombre o ciudad de un cliente ya registrado. | G19: IdCliente, CampoAModificar, NuevoValor | H19: Numérico Entero, Texto | I19: Cliente a modificar y el dato nuevo | J19: Objeto Cliente | K19: Cliente con los datos actualizados | O19: Teléfono no editable aquí | P19: Cambiar el Teléfono requiere el flujo de fusión de clientes, no esta operación | Q19: El cliente no existe | R19: Informar que no se encontró el registro
A20: Consultar historial de pedidos del cliente | C20: Lista los pedidos asociados a un cliente, del más reciente al más antiguo. | G20: IdCliente | H20: Numérico Entero | I20: Cliente del cual se quiere ver el historial | J20: Lista de objetos Pedido | K20: Pedidos del cliente ordenados por fecha | O20: Solo vendedor o administrador | P20: Únicamente cuentas internas pueden consultar este historial | Q20: El cliente no tiene pedidos aún | R20: Mostrar la lista vacía sin error
A21: Consultar clientes frecuentes | C21: Lista los clientes ordenados por TotalPedidos, de mayor a menor. | G21: CantidadMinimaPedidos | H21: Numérico Entero | I21: Umbral mínimo de pedidos para considerar frecuente | J21: Lista de objetos Cliente | K21: Clientes que superan el umbral indicado | O21: Solo administrador | P21: Pensado para seguimiento comercial, lo consulta el administrador | Q21: Ningún cliente supera el umbral | R21: Mostrar un mensaje de "sin resultados"

Sheet DetallePedido
A1: <-Volver al inicio
A2: Objeto de Dominio: | B2: ='Listado Objetos de Dominio'!$A$12 -> DetallePedido
A3: Descripción: | B3: ='Listado Objetos de Dominio'!$B$12 -> Objeto de dominio de ruptura que representa cada línea de producto dentro de un pedido, con su cantidad y precio congelados.
A4: Atributo | B4: Tipo de Dato | C4: Longitud mínima | D4: Longitud máxima | E4: Precisión | F4: Rango Inicial | G4: Rango Final | H4: Formato | I4: Valor por defecto | J4: Regla especial | K4: ¿Auto generado? | L4: ¿Calculado? | M4: ¿Obligatorio? | N4: ¿Sensible? | O4: ¿Identifica al registro? | P4: Descripción | Q4: =A18 -> Crear línea de detalle | R4: =A19 -> Consultar detalle de un pedido | S4: =A20 -> Calcular subtotal de la línea | T4: =A21 -> Consultar historial de ventas por producto
A5: IdDetallePedido | B5: Numérico Entero | C5: 1 | D5: 7 | E5: N/A | F5: 1 | G5: N/A | H5: Numérico | I5: N/A | J5: Único para cada línea de pedido | K5: Sí, por el propio sistema | L5: No | M5: Sí | N5: No | O5: Sí | P5: Identificador único de la línea dentro del pedido
A6: IdPedido | B6: Numérico Entero | C6: 1 | D6: 6 | E6: N/A | F6: 1 | G6: N/A | H6: Numérico | I6: N/A | J6: Debe corresponder a un pedido existente | K6: No | L6: No | M6: Sí | N6: No | O6: No | P6: Pedido al que pertenece esta línea
